Workbook

Sheet Summary
A1: Value at Risk - Portfolio of JPM, MS & BAC (1-day, $1,000,000, equal weights by default)
A2: Data: Yahoo Finance daily adjusted close, 2024-10-31 to 2026-10-30 (500 daily returns). Change weights / value / holding period on each method sheet (yellow cells).
A4: Confidence level | B4: Variance-Covariance VaR | C4: Historical VaR | D4: Monte Carlo VaR
A5: 0.9 | B5: =VarCov_Method!$D$39 -> 19044.603 | C5: =Historical_Method!$E$16 -> 17262.92 | D5: =MonteCarlo_Method!$E$29 -> 19132.083
A6: 0.95 | B6: =VarCov_Method!$D$40 -> 24709.757 | C6: =Historical_Method!$E$17 -> 23940.841 | D6: =MonteCarlo_Method!$E$30 -> 25023.054
A7: 0.99 | B7: =VarCov_Method!$D$41 -> 35336.643 | C7: =Historical_Method!$E$18 -> 42713.764 | D7: =MonteCarlo_Method!$E$31 -> 35552.568
A10: How to read this workbook
A12: Sheets
A13: Data - Step 1 & 2 for every method: Yahoo Finance prices and daily returns.
A14: Backtesting - rolling 250-day out-of-sample VaR for all 3 methods, exceptions, Basel Traffic Light and Kupiec POF test.
A15: VarCov_Method - parametric VaR using mean, std dev, covariance matrix and Z-scores.
A16: Historical_Method - VaR from the actual distribution of past portfolio returns.
A17: MonteCarlo_Method - VaR from 10,000 correlated simulated scenarios (press F9 to re-simulate).
A18: VaR definition: the loss that will not be exceeded with X% confidence over the holding period (e.g. 95% 1-day VaR of $20k = on 95 out of 100 days the loss should be below $20k).

Sheet Data
A1: STEP 1 & 2: Collect price data and calculate daily returns
A2: Source: Yahoo Finance (yfinance), daily adjusted close (dividends/splits adjusted). 2024-10-31 to 2026-10-30 | 501 prices -> 500 daily returns
A3: Daily simple return formula: R_t = P_t / P_(t-1) - 1 (log return shown for reference: LN(P_t/P_(t-1)))
A5: Date | B5: JPM Adj Close | C5: MS Adj Close | D5: BAC Adj Close | F5: JPM Return | G5: MS Return | H5: BAC Return | J5: JPM Log Return | K5: MS Log Return | L5: BAC Log Return
A6: 45596 | B6: 213.21313 | C6: 110.57666 | D6: 40.005711
A7: 45597 | B7: 214.19315 | C7: 111.14738 | D7: 39.948311 | F7: =B7/B6-1 -> 0.0045963912 | G7: =C7/C6-1 -> 0.0051613468 | H7: =D7/D6-1 -> -0.0014347889 | J7: =LN(B7/B6) -> 0.0045858601 | K7: =LN(C7/C6) -> 0.0051480727 | L7: =LN(D7/D6) -> -0.0014358192
A8: 45600 | B8: 211.15709 | C8: 110.47202 | D8: 39.536972 | F8: =B8/B7-1 -> -0.014174387 | G8: =C8/C7-1 -> -0.0060763397 | H8: =D8/D7-1 -> -0.010296776 | J8: =LN(B8/B7) -> -0.014275803 | K8: =LN(C8/C7) -> -0.0060948757 | L8: =LN(D8/D7) -> -0.010350154
A9: 45601 | B9: 212.80003 | C9: 112.06052 | D9: 40.063099 | F9: =B9/B8-1 -> 0.0077806733 | G9: =C9/C8-1 -> 0.014379216 | H9: =D9/D8-1 -> 0.013307212 | J9: =LN(B9/B8) -> 0.00775056 | K9: =LN(C9/C8) -> 0.014276816 | L9: =LN(D9/D8) -> 0.013219449
A10: 45602 | B10: 237.36678 | C10: 125.0729 | D10: 43.439957 | F10: =B10/B9-1 -> 0.1154452 | G10: =C10/C9-1 -> 0.11611924 | H10: =D10/D9-1 -> 0.084288481 | J10: =LN(B10/B9) -> 0.10925361 | K10: =LN(C10/C9) -> 0.10985771 | L10: =LN(D10/D9) -> 0.080923994
A11: 45603 | B11: 227.10583 | C11: 122.17175 | D11: 42.827724 | F11: =B11/B10-1 -> -0.043228209 | G11: =C11/C10-1 -> -0.023195701 | H11: =D11/D10-1 -> -0.014093757 | J11: =LN(B11/B10) -> -0.044190379 | K11: =LN(C11/C10) -> -0.023468955 | L11: =LN(D11/D10) -> -0.014194017
A12: 45604 | B12: 227.68225 | C12: 123.20855 | D12: 43.172112 | F12: =B12/B11-1 -> 0.0025380943 | G12: =C12/C11-1 -> 0.0084864483 | H12: =D12/D11-1 -> 0.0080412177 | J12: =LN(B12/B11) -> 0.0025348787 | K12: =LN(C12/C11) -> 0.0084506408 | L12: =LN(D12/D11) -> 0.0080090594
A13: 45607 | B13: 229.90164 | C13: 127.00382 | D13: 44.080898 | F13: =B13/B12-1 -> 0.0097477553 | G13: =C13/C12-1 -> 0.030803648 | H13: =D13/D12-1 -> 0.02105032 | J13: =LN(B13/B12) -> 0.0097005524 | K13: =LN(C13/C12) -> 0.030338739 | L13: =LN(D13/D12) -> 0.020831823
A14: 45608 | B14: 230.16106 | C14: 125.8529 | D14: 43.870441 | F14: =B14/B13-1 -> 0.0011283724 | G14: =C14/C13-1 -> -0.0090621263 | H14: =D14/D13-1 -> -0.0047743321 | J14: =LN(B14/B13) -> 0.0011277363 | K14: =LN(C14/C13) -> -0.0091034372 | L14: =LN(D14/D13) -> -0.0047857656
A15: 45609 | B15: 231.69827 | C15: 126.2809 | D15: 43.880001 | F15: =B15/B14-1 -> 0.0066788718 | G15: =C15/C14-1 -> 0.0034008069 | H15: =D15/D14-1 -> 0.00021790598 | J15: =LN(B15/B14) -> 0.0066566669 | K15: =LN(C15/C14) -> 0.0033950372 | L15: =LN(D15/D14) -> 0.00021788224
A16: 45610 | B16: 232.38042 | C16: 125.967 | D16: 43.908703 | F16: =B16/B15-1 -> 0.0029441055 | G16: =C16/C15-1 -> -0.002485698 | H16: =D16/D15-1 -> 0.00065409712 | J16: =LN(B16/B15) -> 0.0029397801 | K16: =LN(C16/C15) -> -0.0024887925 | L16: =LN(D16/D15) -> 0.00065388329
A17: 45611 | B17: 235.68546 | C17: 127.51746 | D17: 44.721828 | F17: =B17/B16-1 -> 0.014222534 | G17: =C17/C16-1 -> 0.012308468 | H17: =D17/D16-1 -> 0.018518552 | J17: =LN(B17/B16) -> 0.014122343 | K17: =LN(C17/C16) -> 0.012233335 | L17: =LN(D17/D16) -> 0.018349172
A18: 45614 | B18: 235.41644 | C18: 127.25115 | D18: 44.693127 | F18: =B18/B17-1 -> -0.0011414046 | G18: =C18/C17-1 -> -0.0020884327 | H18: =D18/D17-1 -> -0.00064178463 | J18: =LN(B18/B17) -> -0.0011420564 | K18: =LN(C18/C17) -> -0.0020906166 | L18: =LN(D18/D17) -> -0.00064199066
... A506: 46325 | B506: 337.04001 | C506: 184.3 | D506: 50.009998 | F506: =B506/B505-1 -> -0.019034805 | G506: =C506/C505-1 -> -0.024093211 | H506: =D506/D505-1 -> -0.022096228 | J506: =LN(B506/B505) -> -0.019218299 | K506: =LN(C506/C505) -> -0.0243882 | L506: =LN(D506/D505) -> -0.022344006

Sheet VarCov_Method
A1: VaR - Variance-Covariance (Parametric / Delta-Normal) Method | K1: Method notes
A3: INPUTS (yellow cells are editable) | K3: Steps performed
A4: Portfolio value ($) | B4: 1000000 | K4: 1. Collect data: downloaded daily adjusted closing prices for JPM, MS and BAC from Yahoo Finance (Data sheet).
A5: Holding period (days) | B5: 1 | K5: 2. Calculate returns: daily simple returns R_t = P_t / P_(t-1) - 1 for each stock.
A6: Stock | B6: Weight | C6: Position ($) | K6: 3. Calculate mean (AVERAGE) and standard deviation (STDEV.S) of each stock's daily returns.
A7: JPM (JPMorgan Chase) | B7: 0.33333333 | C7: =$B$4*B7 -> 333333.33 | K7: 4. Build the variance-covariance matrix (COVARIANCE.S) - captures how the stocks move together (correlation shown alongside).
A8: MS (Morgan Stanley) | B8: 0.33333333 | C8: =$B$4*B8 -> 333333.33 | K8: 5. Combine with portfolio weights: portfolio variance = w' x COV x w; portfolio sigma = SQRT(variance); portfolio mean = SUMPRODUCT(w, mu).
A9: BAC (Bank of America) | B9: 0.33333333 | C9: =$B$4*B9 -> 333333.33 | K9: 6. Get Z-score for 90% / 95% / 99% with NORM.S.INV(CI) (1.2816 / 1.6449 / 2.3263).
A10: Total | B10: =SUM(B7:B9) -> 1 | C10: =SUM(C7:C9) -> 1000000 | K10: 7. VaR = (Z x sigma_p - mu_p) x Portfolio Value x SQRT(holding period). Zero-mean version (Z x sigma x V) also shown.
K11: 8. Diversification benefit = undiversified VaR (sum of stand-alone risks) - portfolio VaR.
A12: STEP 1-2: Data collected & daily returns calculated on 'Data' sheet (Adj Close -> R_t = P_t/P_t-1 - 1)
K13: Assumptions
A14: STEP 3: Mean & standard deviation of daily returns (each stock) | K14: Portfolio (and stock) returns are normally distributed.
A15: Statistic | B15: JPM | C15: MS | D15: BAC | K15: Mean, volatility and correlations are constant (stationary) over the look-back window and the holding period.
A16: Mean daily return =AVERAGE() | B16: =AVERAGE(Data!$F$7:$F$506) -> 0.0010359072 | C16: =AVERAGE(Data!$G$7:$G$506) -> 0.0012091414 | D16: =AVERAGE(Data!$H$7:$H$506) -> 0.00057279405 | K16: Positions are linear in risk factors (no options/convexity) and the portfolio is held constant over the horizon.
A17: Std dev daily =STDEV.S() | B17: =_xlfn.STDEV.S(Data!$F$7:$F$506) -> 0.015510582 | C17: =_xlfn.STDEV.S(Data!$G$7:$G$506) -> 0.019376095 | D17: =_xlfn.STDEV.S(Data!$H$7:$H$506) -> 0.015833217 | K17: Returns are i.i.d., so multi-day VaR scales with SQRT(T) (square-root-of-time rule).
A18: Variance daily =VAR.S() | B18: =_xlfn.VAR.S(Data!$F$7:$F$506) -> 0.00024057815 | C18: =_xlfn.VAR.S(Data!$G$7:$G$506) -> 0.00037543307 | D18: =_xlfn.VAR.S(Data!$H$7:$H$506) -> 0.00025069075
A19: Annualised vol (x SQRT(252)) | B19: =B17*SQRT(252) -> 0.24622286 | C19: =C17*SQRT(252) -> 0.30758598 | D19: =D17*SQRT(252) -> 0.25134452 | K19: Pros
K20: Simple, fast and transparent - only needs means, volatilities and correlations.
A21: STEP 4: Covariance matrix =COVARIANCE.S(Ri, Rj) and correlation matrix =CORREL(Ri, Rj) | K21: Easy to scale to other confidence levels and horizons; easy to decompose risk by position (component/marginal VaR).
A22: Covariance | B22: JPM | C22: MS | D22: BAC | F22: Correlation | G22: JPM | H22: MS | I22: BAC | K22: Explicitly captures diversification through the covariance matrix.
A23: JPM | B23: =_xlfn.COVARIANCE.S(Data!$F$7:$F$506,Data!$F$7:$F$506) -> 0.00024057815 | C23: =_xlfn.COVARIANCE.S(Data!$F$7:$F$506,Data!$G$7:$G$506) -> 0.00023059516 | D23: =_xlfn.COVARIANCE.S(Data!$F$7:$F$506,Data!$H$7:$H$506) -> 0.00019348421 | F23: JPM | G23: =CORREL(Data!$F$7:$F$506,Data!$F$7:$F$506) -> 1 | H23: =CORREL(Data!$F$7:$F$506,Data!$G$7:$G$506) -> 0.76728344 | I23: =CORREL(Data!$F$7:$F$506,Data!$H$7:$H$506) -> 0.78785861
A24: MS | B24: =_xlfn.COVARIANCE.S(Data!$G$7:$G$506,Data!$F$7:$F$506) -> 0.00023059516 | C24: =_xlfn.COVARIANCE.S(Data!$G$7:$G$506,Data!$G$7:$G$506) -> 0.00037543307 | D24: =_xlfn.COVARIANCE.S(Data!$G$7:$G$506,Data!$H$7:$H$506) -> 0.00023677833 | F24: MS | G24: =CORREL(Data!$G$7:$G$506,Data!$F$7:$F$506) -> 0.76728344 | H24: =CORREL(Data!$G$7:$G$506,Data!$G$7:$G$506) -> 1 | I24: =CORREL(Data!$G$7:$G$506,Data!$H$7:$H$506) -> 0.77180312 | K24: Cons
A25: BAC | B25: =_xlfn.COVARIANCE.S(Data!$H$7:$H$506,Data!$F$7:$F$506) -> 0.00019348421 | C25: =_xlfn.COVARIANCE.S(Data!$H$7:$H$506,Data!$G$7:$G$506) -> 0.00023677833 | D25: =_xlfn.COVARIANCE.S(Data!$H$7:$H$506,Data!$H$7:$H$506) -> 0.00025069075 | F25: BAC | G25: =CORREL(Data!$H$7:$H$506,Data!$F$7:$F$506) -> 0.78785861 | H25: =CORREL(Data!$H$7:$H$506,Data!$G$7:$G$506) -> 0.77180312 | I25: =CORREL(Data!$H$7:$H$506,Data!$H$7:$H$506) -> 1 | K25: Normality assumption underestimates fat tails - VaR at 99% is often too low in a crisis.
K26: Poor for non-linear instruments (options) and skewed return distributions.
A27: STEP 5: Portfolio mean, variance and std dev sigma_p^2 = w' * COV * w | K27: Covariance estimates are unstable and backward-looking; correlations tend to rise in crashes.
A28: Item | B28: Value | K28: Like all VaR, says nothing about the size of losses beyond the VaR threshold.
A29: (COV * w) for JPM | B29: =$B$23*$B$7+$C$23*$B$8+$D$23*$B$9 -> 0.00022155251
A30: (COV * w) for MS | B30: =$B$24*$B$7+$C$24*$B$8+$D$24*$B$9 -> 0.00028093552
A31: (COV * w) for BAC | B31: =$B$25*$B$7+$C$25*$B$8+$D$25*$B$9 -> 0.00022698443
A32: Portfolio variance w'·COV·w | B32: =SUMPRODUCT($B$7:$B$9,B29:B31) -> 0.00024315748
A33: Portfolio std dev (daily) sigma_p | B33: =SQRT(B32) -> 0.015593508
A34: Portfolio mean (daily) mu_p = SUMPRODUCT(w, mu) | B34: =$B$7*$B$16+$B$8*$C$16+$B$9*$D$16 -> 0.00093928089
A35: Sum of weighted stand-alone std devs (no diversification) | B35: =$B$7*$B$17+$B$8*$C$17+$B$9*$D$17 -> 0.016906631
A37: STEP 6: Z-score for each confidence level =NORM.S.INV(CI) and VaR = (Z*sigma_p - mu_p) * V * SQRT(T)
A38: Confidence level | B38: Z-score | C38: VaR % (incl. mean) | D38: VaR $ (incl. mean) | E38: VaR $ (zero-mean, Z*sigma*V) | F38: Undiversified VaR $ | G38: Diversification benefit $
A39: 0.9 | B39: =_xlfn.NORM.S.INV(A39) -> 1.2815516 | C39: =(B39*$B$33-$B$34)*SQRT($B$5) -> 0.019044603 | D39: =C39*$B$4 -> 19044.603 | E39: =B39*$B$33*SQRT($B$5)*$B$4 -> 19983.884 | F39: =B39*$B$35*SQRT($B$5)*$B$4 -> 21666.72 | G39: =F39-E39 -> 1682.8355
A40: 0.95 | B40: =_xlfn.NORM.S.INV(A40) -> 1.6448536 | C40: =(B40*$B$33-$B$34)*SQRT($B$5) -> 0.024709757 | D40: =C40*$B$4 -> 24709.757 | E40: =B40*$B$33*SQRT($B$5)*$B$4 -> 25649.038 | F40: =B40*$B$35*SQRT($B$5)*$B$4 -> 27808.934 | G40: =F40-E40 -> 2159.896
A41: 0.99 | B41: =_xlfn.NORM.S.INV(A41) -> 2.3263479 | C41: =(B41*$B$33-$B$34)*SQRT($B$5) -> 0.035336643 | D41: =C41*$B$4 -> 35336.643 | E41: =B41*$B$33*SQRT($B$5)*$B$4 -> 36275.924 | F41: =B41*$B$35*SQRT($B$5)*$B$4 -> 39330.706 | G41: =F41-E41 -> 3054.7821
A43: STEP 7: Interpretation
...

Sheet Historical_Method
A1: VaR - Historical Simulation Method | K1: Method notes
A3: INPUTS (yellow cells are editable) | K3: Steps performed
A4: Portfolio value ($) | B4: 1000000 | K4: 1. Collect data: daily adjusted closing prices of JPM, MS, BAC from Yahoo Finance (Data sheet).
A5: Holding period (days) | B5: 1 | K5: 2. Calculate returns: daily simple returns for each stock.
A6: Stock | B6: Weight | C6: Position ($) | K6: 3. Calculate the portfolio's daily return for every historical day = SUMPRODUCT(weights, stock returns); P&L = return x portfolio value. (Each past day is a 'scenario' replayed on today's portfolio.)
A7: JPM (JPMorgan Chase) | B7: 0.33333333 | C7: =$B$4*B7 -> 333333.33 | K7: 4. Sort portfolio returns from worst to best (SMALL function, columns H-I).
A8: MS (Morgan Stanley) | B8: 0.33333333 | C8: =$B$4*B8 -> 333333.33 | K8: 5. VaR = the (1-CI) percentile of the sorted returns: PERCENTILE.INC(returns, 10% / 5% / 1%) x V. Rank method (k-th worst of N) shown as a check.
A9: BAC (Bank of America) | B9: 0.33333333 | C9: =$B$4*B9 -> 333333.33 | K9: 6. Expected Shortfall (CVaR) = average loss on days worse than VaR - shown as a bonus tail-risk measure.
A10: Total | B10: =SUM(B7:B9) -> 1 | C10: =SUM(C7:C9) -> 1000000
K11: Assumptions
A12: STEP 1-2: Data collected & daily returns calculated on 'Data' sheet | K12: The future will behave like the past - the historical window is representative of tomorrow's risk.
K13: Every historical day is equally likely (equal weighting of observations).
A14: STEP 4-5: Sort returns (worst -> best) & read the (1-CI) percentile: VaR = -PERCENTILE.INC(port. returns, 1-CI) x V | K14: No distributional assumption (non-parametric) - correlations are embedded in the actual data.
A15: Confidence level | B15: Tail prob (1-CI) | C15: Percentile return | D15: VaR % (1-day) | E15: VaR $ (x SQRT(T)) | F15: Rank-method: k = ROUNDUP((1-CI)*N) | G15: k-th worst return | H15: VaR $ (rank method) | I15: Expected Shortfall (CVaR) $ | K15: Multi-day VaR uses SQRT(T) scaling (assumes i.i.d. returns).
A16: 0.9 | B16: =1-A16 -> 0.1 | C16: =_xlfn.PERCENTILE.INC($E$25:$E$524,B16) -> -0.01726292 | D16: =-C16 -> 0.01726292 | E16: =D16*$B$4*SQRT($B$5) -> 17262.92 | F16: =ROUNDUP(B16*$B$20,0) -> 50 | G16: =SMALL($E$25:$E$524,F16) -> -0.01742674 | H16: =-G16*$B$4*SQRT($B$5) -> 17426.74 | I16: =-AVERAGEIF($E$25:$E$524,"<="&C16)*$B$4*SQRT($B$5) -> 28403.398
A17: 0.95 | B17: =1-A17 -> 0.05 | C17: =_xlfn.PERCENTILE.INC($E$25:$E$524,B17) -> -0.023940841 | D17: =-C17 -> 0.023940841 | E17: =D17*$B$4*SQRT($B$5) -> 23940.841 | F17: =ROUNDUP(B17*$B$20,0) -> 25 | G17: =SMALL($E$25:$E$524,F17) -> -0.024693286 | H17: =-G17*$B$4*SQRT($B$5) -> 24693.286 | I17: =-AVERAGEIF($E$25:$E$524,"<="&C17)*$B$4*SQRT($B$5) -> 36848.666 | K17: Pros
A18: 0.99 | B18: =1-A18 -> 0.01 | C18: =_xlfn.PERCENTILE.INC($E$25:$E$524,B18) -> -0.042713764 | D18: =-C18 -> 0.042713764 | E18: =D18*$B$4*SQRT($B$5) -> 42713.764 | F18: =ROUNDUP(B18*$B$20,0) -> 5 | G18: =SMALL($E$25:$E$524,F18) -> -0.042934862 | H18: =-G18*$B$4*SQRT($B$5) -> 42934.862 | I18: =-AVERAGEIF($E$25:$E$524,"<="&C18)*$B$4*SQRT($B$5) -> 62258.956 | K18: Simple and intuitive; easy to explain to management/regulators.
K19: No normality assumption - captures fat tails, skew and real correlations present in the data.
A20: Number of historical observations (N) | B20: =COUNT($E$25:$E$524) -> 500 | K20: Handles non-linear instruments naturally by full revaluation.
A22: STEP 3: Portfolio daily return = SUMPRODUCT(weights, stock returns); P&L = return x V. STEP 4: sorted with SMALL() | K22: Cons
K23: Completely dependent on the chosen window - events not in history (e.g. a crash) cannot appear.
A24: Date | B24: JPM Return | C24: MS Return | D24: BAC Return | E24: Portfolio Return | F24: Portfolio P&L ($) | G24: Rank | H24: Sorted Port. Return (worst->best) | I24: Sorted P&L ($) | K24: Few observations in the tail, so 99% VaR is based on only a handful of data points (noisy). | L24: Bin (upper, return) | M24: Frequency
A25: =Data!A7 -> 45597 | B25: =Data!F7 -> 0.0045963912 | C25: =Data!G7 -> 0.0051613468 | D25: =Data!H7 -> -0.0014347889 | E25: =B25*$B$7+C25*$B$8+D25*$B$9 -> 0.0027743164 | F25: =E25*$B$4 -> 2774.3164 | G25: 1 | H25: =SMALL($E$25:$E$524,G25) -> -0.091798847 | I25: =H25*$B$4 -> -91798.847 | K25: Slow to react to changes in volatility regime (all days weighted equally). | L25: -0.06 | M25: =COUNTIFS($E$25:$E$524,"<="&L25) -> 2
A26: =Data!A8 -> 45600 | B26: =Data!F8 -> -0.014174387 | C26: =Data!G8 -> -0.0060763397 | D26: =Data!H8 -> -0.010296776 | E26: =B26*$B$7+C26*$B$8+D26*$B$9 -> -0.010182501 | F26: =E26*$B$4 -> -10182.501 | G26: 2 | H26: =SMALL($E$25:$E$524,G26) -> -0.075307155 | I26: =H26*$B$4 -> -75307.155 | K26: Needs a lot of clean historical data. | L26: -0.055 | M26: =COUNTIFS($E$25:$E$524,"<="&L26,$E$25:$E$524,">"&L25) -> 0
A27: =Data!A9 -> 45601 | B27: =Data!F9 -> 0.0077806733 | C27: =Data!G9 -> 0.014379216 | D27: =Data!H9 -> 0.013307212 | E27: =B27*$B$7+C27*$B$8+D27*$B$9 -> 0.011822367 | F27: =E27*$B$4 -> 11822.367 | G27: 3 | H27: =SMALL($E$25:$E$524,G27) -> -0.053535549 | I27: =H27*$B$4 -> -53535.549 | L27: -0.05 | M27: =COUNTIFS($E$25:$E$524,"<="&L27,$E$25:$E$524,">"&L26) -> 1
A28: =Data!A10 -> 45602 | B28: =Data!F10 -> 0.1154452 | C28: =Data!G10 -> 0.11611924 | D28: =Data!H10 -> 0.084288481 | E28: =B28*$B$7+C28*$B$8+D28*$B$9 -> 0.10528431 | F28: =E28*$B$4 -> 105284.31 | G28: 4 | H28: =SMALL($E$25:$E$524,G28) -> -0.047718366 | I28: =H28*$B$4 -> -47718.366 | L28: -0.045 | M28: =COUNTIFS($E$25:$E$524,"<="&L28,$E$25:$E$524,">"&L27) -> 1
A29: =Data!A11 -> 45603 | B29: =Data!F11 -> -0.043228209 | C29: =Data!G11 -> -0.023195701 | D29: =Data!H11 -> -0.014093757 | E29: =B29*$B$7+C29*$B$8+D29*$B$9 -> -0.026839222 | F29: =E29*$B$4 -> -26839.222 | G29: 5 | H29: =SMALL($E$25:$E$524,G29) -> -0.042934862 | I29: =H29*$B$4 -> -42934.862 | L29: -0.04 | M29: =COUNTIFS($E$25:$E$524,"<="&L29,$E$25:$E$524,">"&L28) -> 3
A30: =Data!A12 -> 45604 | B30: =Data!F12 -> 0.0025380943 | C30: =Data!G12 -> 0.0084864483 | D30: =Data!H12 -> 0.0080412177 | E30: =B30*$B$7+C30*$B$8+D30*$B$9 -> 0.0063552534 | F30: =E30*$B$4 -> 6355.2534 | G30: 6 | H30: =SMALL($E$25:$E$524,G30) -> -0.042711531 | I30: =H30*$B$4 -> -42711.531 | L30: -0.035 | M30: =COUNTIFS($E$25:$E$524,"<="&L30,$E$25:$E$524,">"&L29) -> 2
A31: =Data!A13 -> 45607 | B31: =Data!F13 -> 0.0097477553 | C31: =Data!G13 -> 0.030803648 | D31: =Data!H13 -> 0.02105032 | E31: =B31*$B$7+C31*$B$8+D31*$B$9 -> 0.020533908 | F31: =E31*$B$4 -> 20533.908 | G31: 7 | H31: =SMALL($E$25:$E$524,G31) -> -0.040125734 | I31: =H31*$B$4 -> -40125.734 | L31: -0.03 | M31: =COUNTIFS($E$25:$E$524,"<="&L31,$E$25:$E$524,">"&L30) -> 4
A32: =Data!A14 -> 45608 | B32: =Data!F14 -> 0.0011283724 | C32: =Data!G14 -> -0.0090621263 | D32: =Data!H14 -> -0.0047743321 | E32: =B32*$B$7+C32*$B$8+D32*$B$9 -> -0.0042360287 | F32: =E32*$B$4 -> -4236.0287 | G32: 8 | H32: =SMALL($E$25:$E$524,G32) -> -0.037227695 | I32: =H32*$B$4 -> -37227.695 | L32: -0.025 | M32: =COUNTIFS($E$25:$E$524,"<="&L32,$E$25:$E$524,">"&L31) -> 9
A33: =Data!A15 -> 45609 | B33: =Data!F15 -> 0.0066788718 | C33: =Data!G15 -> 0.0034008069 | D33: =Data!H15 -> 0.00021790598 | E33: =B33*$B$7+C33*$B$8+D33*$B$9 -> 0.0034325282 | F33: =E33*$B$4 -> 3432.5282 | G33: 9 | H33: =SMALL($E$25:$E$524,G33) -> -0.035049856 | I33: =H33*$B$4 -> -35049.856 | L33: -0.02 | M33: =COUNTIFS($E$25:$E$524,"<="&L33,$E$25:$E$524,">"&L32) -> 11
A34: =Data!A16 -> 45610 | B34: =Data!F16 -> 0.0029441055 | C34: =Data!G16 -> -0.002485698 | D34: =Data!H16 -> 0.00065409712 | E34: =B34*$B$7+C34*$B$8+D34*$B$9 -> 0.00037083488 | F34: =E34*$B$4 -> 370.83488 | G34: 10 | H34: =SMALL($E$25:$E$524,G34) -> -0.03495718 | I34: =H34*$B$4 -> -34957.18 | L34: -0.015 | M34: =COUNTIFS($E$25:$E$524,"<="&L34,$E$25:$E$524,">"&L33) -> 26
A35: =Data!A17 -> 45611 | B35: =Data!F17 -> 0.014222534 | C35: =Data!G17 -> 0.012308468 | D35: =Data!H17 -> 0.018518552 | E35: =B35*$B$7+C35*$B$8+D35*$B$9 -> 0.015016518 | F35: =E35*$B$4 -> 15016.518 | G35: 11 | H35: =SMALL($E$25:$E$524,G35) -> -0.033317847 | I35: =H35*$B$4 -> -33317.847 | L35: -0.01 | M35: =COUNTIFS($E$25:$E$524,"<="&L35,$E$25:$E$524,">"&L34) -> 26
A36: =Data!A18 -> 45614 | B36: =Data!F18 -> -0.0011414046 | C36: =Data!G18 -> -0.0020884327 | D36: =Data!H18 -> -0.00064178463 | E36: =B36*$B$7+C36*$B$8+D36*$B$9 -> -0.0012905406 | F36: =E36*$B$4 -> -1290.5406 | G36: 12 | H36: =SMALL($E$25:$E$524,G36) -> -0.033268186 | I36: =H36*$B$4 -> -33268.186 | L36: -0.005 | M36: =COUNTIFS($E$25:$E$524,"<="&L36,$E$25:$E$524,">"&L35) -> 57
A37: =Data!A19 -> 45615 | B37: =Data!F19 -> -0.0079174232 | C37: =Data!G19 -> -0.011511558 | D37: =Data!H19 -> -0.0066351799 | E37: =B37*$B$7+C37*$B$8+D37*$B$9 -> -0.0086880537 | F37: =E37*$B$4 -> -8688.0537 | G37: 13 | H37: =SMALL($E$25:$E$524,G37) -> -0.03112819 | I37: =H37*$B$4 -> -31128.19 | L37: 0 | M37: =COUNTIFS($E$25:$E$524,"<="&L37,$E$25:$E$524,">"&L36) -> 69
A38: =Data!A20 -> 45616 | B38: =Data!F20 -> -0.0095026166 | C38: =Data!G20 -> -0.0041590797 | D38: =Data!H20 -> -0.0075413954 | E38: =B38*$B$7+C38*$B$8+D38*$B$9 -> -0.0070676972 | F38: =E38*$B$4 -> -7067.6972 | G38: 14 | H38: =SMALL($E$25:$E$524,G38) -> -0.028739572 | I38: =H38*$B$4 -> -28739.572 | L38: 0.005 | M38: =COUNTIFS($E$25:$E$524,"<="&L38,$E$25:$E$524,">"&L37) -> 106
... A49: =Data!A31 -> 45632 | B49: =Data!F31 -> 0.0076584834 | C49: =Data!G31 -> -0.0027624241 | D49: =Data!H31 -> 0.00021389325 | E49: =B49*$B$7+C49*$B$8+D49*$B$9 -> 0.0017033175 | F49: =E49*$B$4 -> 1703.3175 | G49: 25 | H49: =SMALL($E$25:$E$524,G49) -> -0.024693286 | I49: =H49*$B$4 -> -24693.286 | L49: 0.06 | M49: =COUNTIFS($E$25:$E$524,"<="&L49,$E$25:$E$524,">"&L48) -> 0
A50: =Data!A32 -> 45635 | B50: =Data!F32 -> -0.014351563 | C50: =Data!G32 -> -0.010618718 | D50: =Data!H32 -> -0.017968026 | E50: =B50*$B$7+C50*$B$8+D50*$B$9 -> -0.014312769 | F50: =E50*$B$4 -> -14312.769 | G50: 26 | H50: =SMALL($E$25:$E$524,G50) -> -0.023901239 | I50: =H50*$B$4 -> -23901.239
A51: =Data!A33 -> 45636 | B51: =Data!F33 -> -0.003896509 | C51: =Data!G33 -> -0.013921307 | D51: =Data!H33 -> -0.0034850275 | E51: =B51*$B$7+C51*$B$8+D51*$B$9 -> -0.007100948 | F51: =E51*$B$4 -> -7100.948 | G51: 27 | H51: =SMALL($E$25:$E$524,G51) -> -0.02309756 | I51: =H51*$B$4 -> -23097.56
A52: =Data!A34 -> 45637 | B52: =Data!F34 -> 0.0027588972 | C52: =Data!G34 -> 0.0063096308 | D52: =Data!H34 -> 0.0072132127 | E52: =B52*$B$7+C52*$B$8+D52*$B$9 -> 0.0054272469 | F52: =E52*$B$4 -> 5427.2469 | G52: 28 | H52: =SMALL($E$25:$E$524,G52) -> -0.022789553 | I52: =H52*$B$4 -> -22789.553
...

Sheet MonteCarlo_Method
A1: VaR - Monte Carlo Simulation Method (correlated, multivariate normal) | K1: Method notes
A3: INPUTS (yellow cells are editable) | K3: Steps performed
A4: Portfolio value ($) | B4: 1000000 | K4: 1. Collect data: daily adjusted closing prices of JPM, MS, BAC from Yahoo Finance (Data sheet).
A5: Holding period (days) | B5: 1 | K5: 2. Calculate returns: daily simple returns for each stock.
A6: Stock | B6: Weight | C6: Position ($) | K6: 3. Estimate parameters from history: mean (AVERAGE), standard deviation (STDEV.S) and covariance matrix (COVARIANCE.S).
A7: JPM (JPMorgan Chase) | B7: 0.33333333 | C7: =$B$4*B7 -> 333333.33 | K7: 4. Cholesky decomposition of the covariance matrix (COV = L x L') so simulated stock returns keep their historical correlations.
A8: MS (Morgan Stanley) | B8: 0.33333333 | C8: =$B$4*B8 -> 333333.33 | K8: 5. Generate 10,000 scenarios: 3 independent standard normals Z = NORM.S.INV(RAND()) per scenario, then correlated returns R = mu + L x Z.
A9: BAC (Bank of America) | B9: 0.33333333 | C9: =$B$4*B9 -> 333333.33 | K9: 6. Portfolio return per scenario = SUMPRODUCT(weights, simulated returns); P&L = return x portfolio value.
A10: Total | B10: =SUM(B7:B9) -> 1 | C10: =SUM(C7:C9) -> 1000000 | K10: 7. VaR = -(1-CI) percentile of the simulated returns x V, for 90% / 95% / 99%. Expected Shortfall shown as bonus.
K11: 8. Re-run (F9) to see simulation noise; more simulations = more stable VaR.
A12: STEP 1-3: Data & returns on 'Data' sheet; mean / std dev / covariance estimated from history
A13: Parameter | B13: JPM | C13: MS | D13: BAC | K13: Assumptions
A14: Mean daily return (mu) | B14: =AVERAGE(Data!$F$7:$F$506) -> 0.0010359072 | C14: =AVERAGE(Data!$G$7:$G$506) -> 0.0012091414 | D14: =AVERAGE(Data!$H$7:$H$506) -> 0.00057279405 | K14: Returns follow the chosen stochastic model - here a multivariate normal distribution with parameters estimated from history.
A15: Std dev daily (sigma) | B15: =_xlfn.STDEV.S(Data!$F$7:$F$506) -> 0.015510582 | C15: =_xlfn.STDEV.S(Data!$G$7:$G$506) -> 0.019376095 | D15: =_xlfn.STDEV.S(Data!$H$7:$H$506) -> 0.015833217 | K15: Mean, volatility and correlations are constant over the horizon.
A16: Covariance matrix | B16: JPM | C16: MS | D16: BAC | K16: The random number generator is good and the number of simulations is large enough for convergence.
A17: JPM | B17: =_xlfn.COVARIANCE.S(Data!$F$7:$F$506,Data!$F$7:$F$506) -> 0.00024057815 | C17: =_xlfn.COVARIANCE.S(Data!$F$7:$F$506,Data!$G$7:$G$506) -> 0.00023059516 | D17: =_xlfn.COVARIANCE.S(Data!$F$7:$F$506,Data!$H$7:$H$506) -> 0.00019348421 | K17: Multi-day VaR scaled by SQRT(T) (or simulate a multi-day path instead).
A18: MS | B18: =_xlfn.COVARIANCE.S(Data!$G$7:$G$506,Data!$F$7:$F$506) -> 0.00023059516 | C18: =_xlfn.COVARIANCE.S(Data!$G$7:$G$506,Data!$G$7:$G$506) -> 0.00037543307 | D18: =_xlfn.COVARIANCE.S(Data!$G$7:$G$506,Data!$H$7:$H$506) -> 0.00023677833
A19: BAC | B19: =_xlfn.COVARIANCE.S(Data!$H$7:$H$506,Data!$F$7:$F$506) -> 0.00019348421 | C19: =_xlfn.COVARIANCE.S(Data!$H$7:$H$506,Data!$G$7:$G$506) -> 0.00023677833 | D19: =_xlfn.COVARIANCE.S(Data!$H$7:$H$506,Data!$H$7:$H$506) -> 0.00025069075 | K19: Pros
K20: Most flexible method - can use any distribution (fat-tailed t, GARCH, jumps) and model complex/non-linear instruments and path dependency.
A21: STEP 4: Cholesky decomposition COV = L x L' (used to make the random shocks correlated) | K21: Generates a full P&L distribution, so ES/CVaR and any percentile are easy to obtain.
A22: L (lower-triangular) | B22: JPM | C22: MS | D22: BAC | K22: Not limited to scenarios that occurred in history.
A23: JPM | B23: =SQRT($B$17) -> 0.015510582 | C23: 0 | D23: 0
A24: MS | B24: =$B$18/$B$23 -> 0.014866957 | C24: =SQRT($C$18-$B$24^2) -> 0.012426047 | D24: 0 | K24: Cons
A25: BAC | B25: =$B$19/$B$23 -> 0.012474336 | C25: =($C$19-$B$25*$B$24)/$C$24 -> 0.004130268 | D25: =SQRT($D$19-$B$25^2-$C$25^2) -> 0.0088330387 | K25: Computationally heavy (many simulations; slow in Excel for large portfolios).
K26: Model risk - results are only as good as the assumed distribution and parameters (here normal, so similar to Var-Cov).
A27: STEP 7: VaR from the simulated distribution VaR = -PERCENTILE.INC(simulated P&L, 1-CI) | K27: Results change between runs (simulation/sampling error).
A28: Confidence level | B28: Tail prob (1-CI) | C28: Simulated percentile return | D28: VaR % (1-day) | E28: VaR $ (x SQRT(T)) | F28: Expected Shortfall (CVaR) $ | K28: More complex to build, validate and explain.
A29: 0.9 | B29: =1-A29 -> 0.1 | C29: =_xlfn.PERCENTILE.INC($H$40:$H$10039,B29) -> -0.019132083 | D29: =-C29 -> 0.019132083 | E29: =D29*$B$4*SQRT($B$5) -> 19132.083 | F29: =-AVERAGEIF($H$40:$H$10039,"<="&C29)*$B$4*SQRT($B$5) -> 26625.375
A30: 0.95 | B30: =1-A30 -> 0.05 | C30: =_xlfn.PERCENTILE.INC($H$40:$H$10039,B30) -> -0.025023054 | D30: =-C30 -> 0.025023054 | E30: =D30*$B$4*SQRT($B$5) -> 25023.054 | F30: =-AVERAGEIF($H$40:$H$10039,"<="&C30)*$B$4*SQRT($B$5) -> 31347.672
A31: 0.99 | B31: =1-A31 -> 0.01 | C31: =_xlfn.PERCENTILE.INC($H$40:$H$10039,B31) -> -0.035552568 | D31: =-C31 -> 0.035552568 | E31: =D31*$B$4*SQRT($B$5) -> 35552.568 | F31: =-AVERAGEIF($H$40:$H$10039,"<="&C31)*$B$4*SQRT($B$5) -> 40549.49
A33: Number of simulations | B33: 10000
A34: Mean of simulated portfolio return (check vs. history) | B34: =AVERAGE($H$40:$H$10039) -> 0.00087266022
A35: Std dev of simulated portfolio return (check) | B35: =_xlfn.STDEV.S($H$40:$H$10039) -> 0.015504529
A36: Press F9 to re-run the simulation (RAND() is volatile) - VaR will move slightly each run.
A38: STEP 5: Random normals Z = NORM.S.INV(RAND()); correlated returns R = mu + L x Z. STEP 6: portfolio return & P&L for each scenario
A39: Sim # | B39: Z1 | C39: Z2 | D39: Z3 | E39: JPM sim return | F39: MS sim return | G39: BAC sim return | H39: Portfolio return | I39: Portfolio P&L ($)
A40: 1 | B40: =_xlfn.NORM.S.INV(RAND()) -> -0.29094838 | C40: =_xlfn.NORM.S.INV(RAND()) -> -2.0656111 | D40: =_xlfn.NORM.S.INV(RAND()) -> -1.6974402 | E40: =$B$14+$B$23*B40 -> -0.0034768716 | F40: =$C$14+$B$24*B40+$C$24*C40 -> -0.028783757 | G40: =$D$14+$B$25*B40+$C$25*C40+$D$25*D40 -> -0.026581677 | H40: =E40*$B$7+F40*$B$8+G40*$B$9 -> -0.019614102 | I40: =H40*$B$4 -> -19614.102
A41: 2 | B41: =_xlfn.NORM.S.INV(RAND()) -> -0.95557978 | C41: =_xlfn.NORM.S.INV(RAND()) -> 1.1691812 | D41: =_xlfn.NORM.S.INV(RAND()) -> 1.248454 | E41: =$B$14+$B$23*B41 -> -0.013785691 | F41: =$C$14+$B$24*B41+$C$24*C41 -> 0.0015308793 | G41: =$D$14+$B$25*B41+$C$25*C41+$D$25*D41 -> 0.0045092452 | H41: =E41*$B$7+F41*$B$8+G41*$B$9 -> -0.0025818556 | I41: =H41*$B$4 -> -2581.8556
A42: 3 | B42: =_xlfn.NORM.S.INV(RAND()) -> -1.5005921 | C42: =_xlfn.NORM.S.INV(RAND()) -> -0.93402864 | D42: =_xlfn.NORM.S.INV(RAND()) -> -0.77962476 | E42: =$B$14+$B$23*B42 -> -0.022239149 | F42: =$C$14+$B$24*B42+$C$24*C42 -> -0.032706381 | G42: =$D$14+$B$25*B42+$C$25*C42+$D$25*D42 -> -0.02889034 | H42: =E42*$B$7+F42*$B$8+G42*$B$9 -> -0.02794529 | I42: =H42*$B$4 -> -27945.29
A43: 4 | B43: =_xlfn.NORM.S.INV(RAND()) -> 0.83394366 | C43: =_xlfn.NORM.S.INV(RAND()) -> -3.0104799 | D43: =_xlfn.NORM.S.INV(RAND()) -> 1.2487577 | E43: =$B$14+$B$23*B43 -> 0.013970859 | F43: =$C$14+$B$24*B43+$C$24*C43 -> -0.02380102 | G43: =$D$14+$B$25*B43+$C$25*C43+$D$25*D43 -> 0.009571924 | H43: =E43*$B$7+F43*$B$8+G43*$B$9 -> -8.6079142e-05 | I43: =H43*$B$4 -> -86.079142
...

Sheet Backtesting
A1: VaR Backtesting - Rolling out-of-sample VaR, Basel Traffic Light & Kupiec POF test | Z1: Backtesting notes
A3: INPUTS | Z3: Steps performed
A4: Estimation window (days) | B4: 250 | Z4: 1. Collect data & returns (Data sheet); daily portfolio return taken from Historical_Method (same weights).
A5: Portfolio value ($) - from Historical sheet | B5: =Historical_Method!$B$4 -> 1000000 | Z5: 2. Rolling window: for each test day, VaR is estimated using ONLY the previous 250 days (no look-ahead). First 250 days are the initial estimation window, the remaining 250 days are the out-of-sample test period.
A6: Kupiec test significance level | B6: 0.05 | Z6: - Var-Cov: (Z x STDEV.S(window) - AVERAGE(window)) x V (STDEV of portfolio returns = SQRT(w'COVw) of the window)
A7: Chi-square(1) critical value =CHISQ.INV.RT(sig,1) | B7: =_xlfn.CHISQ.INV.RT(B6,1) -> 3.8414588 | Z7: - Historical: -PERCENTILE.INC(window, 1-CI) x V
A8: Weights: taken from Historical_Method sheet (portfolio returns column) | Z8: - Monte Carlo: -(mu + sigma x simulated Z-quantile) x V, using 10,000 fixed N(0,1) draws in column AN (common random numbers). Python version simulates all 3 stocks with Cholesky every day, so its MC numbers may differ slightly.
Z9: 3. Exception (breach) = 1 if actual loss (-P&L) > VaR forecast for that day (highlighted red).
A10: Z-scores: analytic (Var-Cov) and simulated quantile of 10,000 fixed N(0,1) draws (Monte Carlo) | Z10: 4. Count exceptions x over T test days; expected = (1-CI) x T.
A11: Confidence level | B11: Analytic Z =NORM.S.INV(CI) | C11: Simulated Z-quantile (1-CI) | Z11: 5. Traffic Light: cumulative binomial P(X<=x) = BINOM.DIST(x,T,p,TRUE). Green < 95%, Yellow 95%-99.99%, Red >= 99.99%. At 99%/250 days = Basel's 0-4 / 5-9 / 10+.
A12: 0.9 | B12: =_xlfn.NORM.S.INV(A12) -> 1.2815516 | C12: =_xlfn.PERCENTILE.INC($AN$31:$AN$10030,1-A12) -> -1.3137682 | Z12: 6. Kupiec POF test: LR = -2ln[(1-p)^(T-x) p^x] + 2ln[(1-x/T)^(T-x) (x/T)^x] ~ chi-square(1). Reject the model if LR > 3.841 (p-value < 5%).
A13: 0.95 | B13: =_xlfn.NORM.S.INV(A13) -> 1.6448536 | C13: =_xlfn.PERCENTILE.INC($AN$31:$AN$10030,1-A13) -> -1.6740935
A14: 0.99 | B14: =_xlfn.NORM.S.INV(A14) -> 2.3263479 | C14: =_xlfn.PERCENTILE.INC($AN$31:$AN$10030,1-A14) -> -2.3738112 | Z14: Assumptions
Z15: Exceptions are independent Bernoulli(p) events - Kupiec ignores whether breaches cluster together.
A16: STEP 4-6: Exception count, Kupiec POF test & Traffic Light zone | Z16: Portfolio composition is constant over the test period; P&L is the clean (hypothetical) P&L of that portfolio.
A17: Method | B17: CI | C17: Test days (T) | D17: Expected exc. (p*T) | E17: Actual exc. (x) | F17: Exception rate | G17: Kupiec LR | H17: p-value =CHISQ.DIST.RT | I17: Kupiec result | J17: Cum. binomial P(X<=x) | K17: Traffic light zone | L17: Basel plus factor (99% only) | Z17: 250 test days is enough to judge the model (in practice power is low, especially at 99%).
A18: Variance-Covariance | B18: 0.9 | C18: =COUNT(D281:D530) -> 250 | D18: =(1-B18)*C18 -> 25 | E18: =SUM(E281:E530) -> 24 | F18: =E18/C18 -> 0.096 | G18: =-2*((C18-E18)*LN(B18)+E18*LN(1-B18))+2*(IF(E18<C18,(C18-E18)*LN(1-F18),0)+IF(E18>0,E18*LN(F18),0)) -> 0.044982138 | H18: =_xlfn.CHISQ.DIST.RT(G18,1) -> 0.83203688 | I18: =IF(G18>$B$7,"Reject","Accept") -> Accept | J18: =_xlfn.BINOM.DIST(E18,C18,1-B18,TRUE) -> 0.46917356 | K18: =IF(J18<0.95,"GREEN",IF(J18<0.9999,"YELLOW","RED")) -> GREEN | L18: n/a
A19: Variance-Covariance | B19: 0.95 | C19: =COUNT(F281:F530) -> 250 | D19: =(1-B19)*C19 -> 12.5 | E19: =SUM(G281:G530) -> 15 | F19: =E19/C19 -> 0.06 | G19: =-2*((C19-E19)*LN(B19)+E19*LN(1-B19))+2*(IF(E19<C19,(C19-E19)*LN(1-F19),0)+IF(E19>0,E19*LN(F19),0)) -> 0.49605532 | H19: =_xlfn.CHISQ.DIST.RT(G19,1) -> 0.48123853 | I19: =IF(G19>$B$7,"Reject","Accept") -> Accept | J19: =_xlfn.BINOM.DIST(E19,C19,1-B19,TRUE) -> 0.81128084 | K19: =IF(J19<0.95,"GREEN",IF(J19<0.9999,"YELLOW","RED")) -> GREEN | L19: n/a | Z19: Pros
A20: Variance-Covariance | B20: 0.99 | C20: =COUNT(H281:H530) -> 250 | D20: =(1-B20)*C20 -> 2.5 | E20: =SUM(I281:I530) -> 5 | F20: =E20/C20 -> 0.02 | G20: =-2*((C20-E20)*LN(B20)+E20*LN(1-B20))+2*(IF(E20<C20,(C20-E20)*LN(1-F20),0)+IF(E20>0,E20*LN(F20),0)) -> 1.9568098 | H20: =_xlfn.CHISQ.DIST.RT(G20,1) -> 0.16185492 | I20: =IF(G20>$B$7,"Reject","Accept") -> Accept | J20: =_xlfn.BINOM.DIST(E20,C20,1-B20,TRUE) -> 0.95881682 | K20: =IF(J20<0.95,"GREEN",IF(J20<0.9999,"YELLOW","RED")) -> YELLOW | L20: =IF(C20<>250,"n/a",IF(E20<=4,0,IF(E20>=10,1,CHOOSE(E20-4,0.4,0.5,0.65,0.75,0.85)))) -> 0.4 | Z20: Traffic Light: simple, regulatory standard (Basel), directly sets the capital multiplier.
A21: Historical | B21: 0.9 | C21: =COUNT(J281:J530) -> 250 | D21: =(1-B21)*C21 -> 25 | E21: =SUM(K281:K530) -> 31 | F21: =E21/C21 -> 0.124 | G21: =-2*((C21-E21)*LN(B21)+E21*LN(1-B21))+2*(IF(E21<C21,(C21-E21)*LN(1-F21),0)+IF(E21>0,E21*LN(F21),0)) -> 1.498347 | H21: =_xlfn.CHISQ.DIST.RT(G21,1) -> 0.22092587 | I21: =IF(G21>$B$7,"Reject","Accept") -> Accept | J21: =_xlfn.BINOM.DIST(E21,C21,1-B21,TRUE) -> 0.91142201 | K21: =IF(J21<0.95,"GREEN",IF(J21<0.9999,"YELLOW","RED")) -> GREEN | L21: n/a | Z21: Kupiec: formal hypothesis test that penalises both too many AND too few exceptions (over-conservative models fail too).
A22: Historical | B22: 0.95 | C22: =COUNT(L281:L530) -> 250 | D22: =(1-B22)*C22 -> 12.5 | E22: =SUM(M281:M530) -> 14 | F22: =E22/C22 -> 0.056 | G22: =-2*((C22-E22)*LN(B22)+E22*LN(1-B22))+2*(IF(E22<C22,(C22-E22)*LN(1-F22),0)+IF(E22>0,E22*LN(F22),0)) -> 0.18269688 | H22: =_xlfn.CHISQ.DIST.RT(G22,1) -> 0.66906576 | I22: =IF(G22>$B$7,"Reject","Accept") -> Accept | J22: =_xlfn.BINOM.DIST(E22,C22,1-B22,TRUE) -> 0.72883631 | K22: =IF(J22<0.95,"GREEN",IF(J22<0.9999,"YELLOW","RED")) -> GREEN | L22: n/a | Z22: Out-of-sample rolling design mimics how a risk desk actually uses VaR each day.
A23: Historical | B23: 0.99 | C23: =COUNT(N281:N530) -> 250 | D23: =(1-B23)*C23 -> 2.5 | E23: =SUM(O281:O530) -> 2 | F23: =E23/C23 -> 0.008 | G23: =-2*((C23-E23)*LN(B23)+E23*LN(1-B23))+2*(IF(E23<C23,(C23-E23)*LN(1-F23),0)+IF(E23>0,E23*LN(F23),0)) -> 0.10843522 | H23: =_xlfn.CHISQ.DIST.RT(G23,1) -> 0.7419327 | I23: =IF(G23>$B$7,"Reject","Accept") -> Accept | J23: =_xlfn.BINOM.DIST(E23,C23,1-B23,TRUE) -> 0.54316897 | K23: =IF(J23<0.95,"GREEN",IF(J23<0.9999,"YELLOW","RED")) -> GREEN | L23: =IF(C23<>250,"n/a",IF(E23<=4,0,IF(E23>=10,1,CHOOSE(E23-4,0.4,0.5,0.65,0.75,0.85)))) -> 0
A24: Monte Carlo | B24: 0.9 | C24: =COUNT(P281:P530) -> 250 | D24: =(1-B24)*C24 -> 25 | E24: =SUM(Q281:Q530) -> 23 | F24: =E24/C24 -> 0.092 | G24: =-2*((C24-E24)*LN(B24)+E24*LN(1-B24))+2*(IF(E24<C24,(C24-E24)*LN(1-F24),0)+IF(E24>0,E24*LN(F24),0)) -> 0.18217132 | H24: =_xlfn.CHISQ.DIST.RT(G24,1) -> 0.66951384 | I24: =IF(G24>$B$7,"Reject","Accept") -> Accept | J24: =_xlfn.BINOM.DIST(E24,C24,1-B24,TRUE) -> 0.385723 | K24: =IF(J24<0.95,"GREEN",IF(J24<0.9999,"YELLOW","RED")) -> GREEN | L24: n/a | Z24: Cons
A25: Monte Carlo | B25: 0.95 | C25: =COUNT(R281:R530) -> 250 | D25: =(1-B25)*C25 -> 12.5 | E25: =SUM(S281:S530) -> 13 | F25: =E25/C25 -> 0.052 | G25: =-2*((C25-E25)*LN(B25)+E25*LN(1-B25))+2*(IF(E25<C25,(C25-E25)*LN(1-F25),0)+IF(E25>0,E25*LN(F25),0)) -> 0.020791913 | H25: =_xlfn.CHISQ.DIST.RT(G25,1) -> 0.88534727 | I25: =IF(G25>$B$7,"Reject","Accept") -> Accept | J25: =_xlfn.BINOM.DIST(E25,C25,1-B25,TRUE) -> 0.62927406 | K25: =IF(J25<0.95,"GREEN",IF(J25<0.9999,"YELLOW","RED")) -> GREEN | L25: n/a | Z25: Both tests only use the COUNT of exceptions - not their timing (use Christoffersen independence test) or size (use ES backtests).
A26: Monte Carlo | B26: 0.99 | C26: =COUNT(T281:T530) -> 250 | D26: =(1-B26)*C26 -> 2.5 | E26: =SUM(U281:U530) -> 4 | F26: =E26/C26 -> 0.016 | G26: =-2*((C26-E26)*LN(B26)+E26*LN(1-B26))+2*(IF(E26<C26,(C26-E26)*LN(1-F26),0)+IF(E26>0,E26*LN(F26),0)) -> 0.76913836 | H26: =_xlfn.CHISQ.DIST.RT(G26,1) -> 0.38048374 | I26: =IF(G26>$B$7,"Reject","Accept") -> Accept | J26: =_xlfn.BINOM.DIST(E26,C26,1-B26,TRUE) -> 0.89218763 | K26: =IF(J26<0.95,"GREEN",IF(J26<0.9999,"YELLOW","RED")) -> GREEN | L26: =IF(C26<>250,"n/a",IF(E26<=4,0,IF(E26>=10,1,CHOOSE(E26-4,0.4,0.5,0.65,0.75,0.85)))) -> 0 | Z26: Low statistical power with 250 observations: a poor 99% model can easily pass.
A27: Basel 99%/250-day table: Green 0-4 exceptions (multiplier 3.0), Yellow 5-9 (3.40/3.50/3.65/3.75/3.85), Red 10+ (4.0). Zones here use the same cumulative-binomial cut-offs (95% / 99.99%) so they apply to every CI. | Z27: Results depend on window length and the specific test period chosen.
A29: STEP 1-3: Daily portfolio P&L, rolling VaR forecast from the PREVIOUS 250 days only, exception = 1 if loss > VaR
A30: Date | B30: Portfolio return | C30: Actual P&L ($) | D30: VC VaR 90% | E30: VC Exc 90% | F30: VC VaR 95% | G30: VC Exc 95% | H30: VC VaR 99% | I30: VC Exc 99% | J30: HS VaR 90% | K30: HS Exc 90% | L30: HS VaR 95% | M30: HS Exc 95% | N30: HS VaR 99% | O30: HS Exc 99% | P30: MC VaR 90% | Q30: MC Exc 90% | R30: MC VaR 95% | S30: MC Exc 95% | T30: MC VaR 99% | U30: MC Exc 99% | V30: -VC VaR 99% (chart) | W30: -HS VaR 99% (chart) | X30: -MC VaR 99% (chart) | AN30: MC fixed N(0,1) draws (seed 42)
A31: =Historical_Method!A25 -> 45597 | B31: =Historical_Method!E25 -> 0.0027743164 | C31: =B31*$B$5 -> 2774.3164 | AN31: 0.30471708
A32: =Historical_Method!A26 -> 45600 | B32: =Historical_Method!E26 -> -0.010182501 | C32: =B32*$B$5 -> -10182.501 | AN32: -1.0399841
A33: =Historical_Method!A27 -> 45601 | B33: =Historical_Method!E27 -> 0.011822367 | C33: =B33*$B$5 -> 11822.367 | AN33: 0.7504512
A34: =Historical_Method!A28 -> 45602 | B34: =Historical_Method!E28 -> 0.10528431 | C34: =B34*$B$5 -> 105284.31 | AN34: 0.94056472
A35: =Historical_Method!A29 -> 45603 | B35: =Historical_Method!E29 -> -0.026839222 | C35: =B35*$B$5 -> -26839.222 | AN35: -1.9510352
A36: =Historical_Method!A30 -> 45604 | B36: =Historical_Method!E30 -> 0.0063552534 | C36: =B36*$B$5 -> 6355.2534 | AN36: -1.3021795
A37: =Historical_Method!A31 -> 45607 | B37: =Historical_Method!E31 -> 0.020533908 | C37: =B37*$B$5 -> 20533.908 | AN37: 0.1278404
A38: =Historical_Method!A32 -> 45608 | B38: =Historical_Method!E32 -> -0.0042360287 | C38: =B38*$B$5 -> -4236.0287 | AN38: -0.31624259
A39: =Historical_Method!A33 -> 45609 | B39: =Historical_Method!E33 -> 0.0034325282 | C39: =B39*$B$5 -> 3432.5282 | AN39: -0.016801158
A40: =Historical_Method!A34 -> 45610 | B40: =Historical_Method!E34 -> 0.00037083488 | C40: =B40*$B$5 -> 370.83488 | AN40: -0.85304393
A41: =Historical_Method!A35 -> 45611 | B41: =Historical_Method!E35 -> 0.015016518 | C41: =B41*$B$5 -> 15016.518 | AN41: 0.87939797
A42: =Historical_Method!A36 -> 45614 | B42: =Historical_Method!E36 -> -0.0012905406 | C42: =B42*$B$5 -> -1290.5406 | AN42: 0.77779194
...
